<?xml version="1.0" encoding="UTF-8"?>
<testng-results skipped="0" failed="1" ignored="0" total="1" passed="0">
  <reporter-output>
  </reporter-output>
  <suite name="Default suite" duration-ms="63" started-at="2018-03-16T05:51:13Z" finished-at="2018-03-16T05:51:13Z">
    <groups>
    </groups>
    <test name="Default test" duration-ms="63" started-at="2018-03-16T05:51:13Z" finished-at="2018-03-16T05:51:13Z">
      <class name="testngasserts.TestNGFail">
        <test-method status="FAIL" signature="testFail()[pri:0, instance:testngasserts.TestNGFail@4e7dc304]" name="testFail" duration-ms="22" started-at="2018-03-16T11:21:13Z" finished-at="2018-03-16T11:21:13Z">
          <exception class="java.lang.AssertionError">
            <message>
              <![CDATA[test purpose]]>
            </message>
            <full-stacktrace>
              <![CDATA[java.lang.AssertionError: test purposeat org.testng.Assert.fail(Assert.java:85)at testngasserts.TestNGFail.testFail(TestNGFail.java:12)at sun.reflect.NativeMethodAccessorImpl.invoke0(Native Method)at sun.reflect.NativeMethodAccessorImpl.invoke(Unknown Source)at sun.reflect.DelegatingMethodAccessorImpl.invoke(Unknown Source)at java.lang.reflect.Method.invoke(Unknown Source)at org.testng.internal.MethodInvocationHelper.invokeMethod(MethodInvocationHelper.java:124)at org.testng.internal.Invoker.invokeMethod(Invoker.java:571)at org.testng.internal.Invoker.invokeTestMethod(Invoker.java:707)at org.testng.internal.Invoker.invokeTestMethods(Invoker.java:979)at org.testng.internal.TestMethodWorker.invokeTestMethods(TestMethodWorker.java:125)at org.testng.internal.TestMethodWorker.run(TestMethodWorker.java:109)at org.testng.TestRunner.privateRun(TestRunner.java:648)at org.testng.TestRunner.run(TestRunner.java:505)at org.testng.SuiteRunner.runTest(SuiteRunner.java:455)at org.testng.SuiteRunner.runSequentially(SuiteRunner.java:450)at org.testng.SuiteRunner.privateRun(SuiteRunner.java:415)at org.testng.SuiteRunner.run(SuiteRunner.java:364)at org.testng.SuiteRunnerWorker.runSuite(SuiteRunnerWorker.java:52)at org.testng.SuiteRunnerWorker.run(SuiteRunnerWorker.java:84)at org.testng.TestNG.runSuitesSequentially(TestNG.java:1187)at org.testng.TestNG.runSuitesLocally(TestNG.java:1116)at org.testng.TestNG.runSuites(TestNG.java:1028)at org.testng.TestNG.run(TestNG.java:996)at org.testng.remote.AbstractRemoteTestNG.run(AbstractRemoteTestNG.java:114)at org.testng.remote.RemoteTestNG.initAndRun(RemoteTestNG.java:251)at org.testng.remote.RemoteTestNG.main(RemoteTestNG.java:77)Caused by: org.openqa.selenium.NoSuchFrameException: user thrown exceptionBuild info: version: '3.8.0', revision: '924c4067df', time: '2017-11-30T11:37:19.049Z'System info: host: 'USER-PC', ip: '192.168.0.100', os.name: 'Windows 7', os.arch: 'amd64', os.version: '6.1', java.version: '1.8.0_151'Driver info: driver.version: unknown... 26 more]]>
            </full-stacktrace>
          </exception> <!-- java.lang.AssertionError -->
          <reporter-output>
          </reporter-output>
        </test-method> <!-- testFail -->
      </class> <!-- testngasserts.TestNGFail -->
    </test> <!-- Default test -->
  </suite> <!-- Default suite -->
</testng-results>
